Workbook

Sheet Library
A1: ID | B1: Room type | C1: Housing fit (est.) | D1: Style | E1: Palette | F1: Materials | G1: Lighting | H1: Layout | I1: Textiles and texture | J1: Furniture style | K1: Mood | L1: Budget tier (est.) | M1: Photo or render | N1: Notes and flags | O1: Photographer | P1: Source URL | Q1: Licence
A2: FL-0001 | B2: living | C2: HDB; condo | D2: Japandi | E2: warm neutral; grey, walnut | F2: dark wood; fabric-heavy | G2: natural-led; feature pendant | H2: open concept | I2: soft layered | J2: low-profile | K2: calm | L2: Mid-range | M2: No | N2: living-dining layout close to a SG condo | O2: Clay Banks (@claybanks) | P2: https://unsplash.com/photos/RDg0Xz_KBdY | Q2: Unsplash Licence
A3: FL-0002 | B3: living | C3: HDB; condo | D3: Japandi | E3: warm neutral; white, oak, navy | F3: light wood; fabric-heavy | G3: natural-led | H3: open concept | I3: smooth | J3: low-profile | K3: calm | L3: Essential | M3: No | N3: long narrow plan similar to HDB living-dining | O3: Fred Kleber (@flaken) | P3: https://unsplash.com/photos/mqEuPwpEvuE | Q3: Unsplash Licence
A4: FL-0003 | B4: living | C4: HDB; condo | D4: Scandinavian | E4: warm neutral; white, cream | F4: light wood; rattan; fabric-heavy | G4: natural-led; floor lamp | H4: semi-open | I4: soft layered | J4: freestanding | K4: calm | L4: Essential | M4: Likely | O4: Spacejoy (@spacejoy) | P4: https://unsplash.com/photos/c0JoR_-2x3E | Q4: Unsplash Licence
A5: FL-0004 | B5: living | C5: HDB; condo | D5: Scandinavian | E5: warm neutral with pastel accents; white, sage, orange | F5: light wood; fabric-heavy | G5: natural-led | H5: closed | I5: soft layered | J5: freestanding | K5: playful | L5: Essential | M5: No | O5: Yehleen gaffney (@yanagirl2020) | P5: https://unsplash.com/photos/raxI_EcyfGw | Q5: Unsplash Licence
A6: FL-0005 | B6: living | C6: HDB; condo | D6: contemporary | E6: cool neutral with bold art; charcoal, slate, brown | F6: fabric-heavy; metal | G6: warm ambient; natural-led | H6: closed | I6: soft layered | J6: statement piece | K6: dramatic | L6: Mid-range | M6: Likely | N6: sculptural chairs and abstract art | O6: mahmoud azmy (@mahmoud_azmy) | P6: https://unsplash.com/photos/8ccOqbNdp1A | Q6: Unsplash Licence
A7: FL-0006 | B7: living | C7: HDB; condo | D7: contemporary | E7: warm neutral; tan, walnut, grey | F7: dark wood; fabric-heavy | G7: cove; warm ambient | H7: closed | I7: soft layered | J7: built-in heavy | K7: cosy | L7: Mid-range | M7: Likely | N7: tray ceiling with cove and panelled TV wall, close to Asian apartment styling; likely a 3D render | O7: Naksha Banwao (@nakshabanwao) | P7: https://unsplash.com/photos/nAFuA8t5K9Y | Q7: Unsplash Licence
A8: FL-0007 | B8: living | C8: condo; landed | D8: contemporary | E8: cool neutral; grey, white, black | F8: concrete; fabric-heavy | G8: natural-led | H8: open concept | I8: smooth | J8: low-profile | K8: calm | L8: Premium | M8: Likely | O8: Aalo Lens (@aalolens) | P8: https://unsplash.com/photos/ugIfsN9l_q4 | Q8: Unsplash Licence
A9: FL-0008 | B9: living | C9: landed | D9: industrial | E9: bold; navy, brick red, grey | F9: metal; fabric-heavy; concrete | G9: natural-led | H9: open concept | I9: woven | J9: freestanding | K9: cosy | L9: Mid-range | M9: No | N9: exposed brick; loft volume unlike SG flats | O9: Anna Sullivan (@aesullivan2010) | P9: https://unsplash.com/photos/FKZsWsFiNDs | Q9: Unsplash Licence
A10: FL-0009 | B10: living | C10: HDB; condo | D10: industrial | E10: earthy; brick red, black, teal | F10: metal; fabric-heavy | G10: warm ambient; floor lamp | H10: closed | I10: soft layered | J10: freestanding | K10: cosy | L10: Essential | M10: No | N10: brick feature wall at apartment scale (tile or wallpaper can replicate) | O10: MAHZA D'BRATA (@mahza_dbrata) | P10: https://unsplash.com/photos/G88ehihe6wQ | Q10: Unsplash Licence
A11: FL-0010 | B11: living | C11: HDB; condo | D11: mid-century | E11: bold; olive green, burnt orange | F11: light wood; fabric-heavy | G11: natural-led | H11: closed | I11: soft layered | J11: statement piece | K11: playful | L11: Essential | M11: Likely | N11: gallery wall, colour-led rather than build-led | O11: Spacejoy (@spacejoy) | P11: https://unsplash.com/photos/q3Qd86sfaoU | Q11: Unsplash Licence
A12: FL-0011 | B12: living | C12: landed | D12: mid-century | E12: earthy; tan leather, sage, white | F12: light wood; fabric-heavy | G12: natural-led | H12: open concept | I12: soft layered | J12: freestanding | K12: airy | L12: Mid-range | M12: No | N12: high ceiling, open plan | O12: Kara Eads (@karaeads) | P12: https://unsplash.com/photos/L7EwHkq1B2s | Q12: Unsplash Licence
A13: FL-0012 | B13: living | C13: condo; landed | D13: modern luxe | E13: warm neutral with black stone; cream, black marble, walnut | F13: marble; dark wood; fabric-heavy | G13: natural-led; warm ambient | H13: open concept | I13: soft layered | J13: statement piece | K13: dramatic | L13: Premium | M13: No | N13: black marble fireplace wall | O13: Ariel Domenden (@hypvisual) | P13: https://unsplash.com/photos/gBqNmxSxnAM | Q13: Unsplash Licence
A14: FL-0013 | B14: living | C14: condo; landed | D14: modern luxe | E14: warm neutral; cream, gold, grey | F14: marble; metal; fabric-heavy | G14: feature pendant; cove | H14: closed | I14: soft layered | J14: statement piece | K14: dramatic | L14: Premium | M14: Likely | N14: crystal chandelier | O14: Aalo Lens (@aalolens) | P14: https://unsplash.com/photos/-QCjahEjubY | Q14: Unsplash Licence
A15: FL-0014 | B15: living | C15: condo; landed | D15: modern luxe | E15: cool neutral with gold; grey, white, brass | F15: marble; metal; fabric-heavy | G15: feature pendant; cove | H15: closed | I15: soft layered | J15: statement piece | K15: dramatic | L15: Premium | M15: Likely | N15: panelled walls and marble floor; likely a 3D render | O15: Ali Moradi (@3dartistmoradi) | P15: https://unsplash.com/photos/nhzhEZvhZ1M | Q15: Unsplash Licence
A16: FL-0015 | B16: living | C16: condo; landed | D16: modern minimalist | E16: cool neutral; charcoal, grey, black | F16: fabric-heavy; metal | G16: cove; natural-led | H16: open concept | I16: smooth | J16: low-profile | K16: calm | L16: Premium | M16: Likely | N16: full-height glazing | O16: Prydumano Design (@prydumanodesign) | P16: https://unsplash.com/photos/vIbxvHj9m9g | Q16: Unsplash Licence
A17: FL-0016 | B17: living | C17: HDB; condo | D17: modern minimalist | E17: warm neutral; beige, cream | F17: fabric-heavy | G17: cove; warm ambient | H17: closed | I17: soft layered | J17: low-profile | K17: cosy | L17: Mid-range | M17: No | N17: curved boucle furniture and cove ceiling, a common SG condo look | O17: Pipcke (@pipcke) | P17: https://unsplash.com/photos/SZ-DsEZxzlg | Q17: Unsplash Licence
A18: FL-0017 | B18: living | C18: HDB; condo | D18: modern minimalist | E18: warm neutral; taupe, grey, blush | F18: fabric-heavy; light wood | G18: cove; warm ambient | H18: closed | I18: soft layered | J18: freestanding | K18: calm | L18: Mid-range | M18: Likely | N18: feature wall panel | O18: POOJAN THANEKAR (@poojanclicks) | P18: https://unsplash.com/photos/-jk2BBoQxSk | Q18: Unsplash Licence
A19: FL-0018 | B19: living | C19: condo; landed | D19: tropical | E19: earthy; white, green, tan | F19: rattan; fabric-heavy; concrete | G19: natural-led; feature pendant | H19: semi-open | I19: woven | J19: low-profile | K19: airy | L19: Premium | M19: Likely | N19: breeze-block screen wall and indoor planting, strong local relevance; likely a 3D render | O19: Jejo Jose (@tomjejojose) | P19: https://unsplash.com/photos/p2oz7Bkk5t4 | Q19: Unsplash Licence
A20: FL-0019 | B20: living | C20: HDB; condo | D20: tropical | E20: warm neutral; white, honey wood | F20: light wood; fabric-heavy | G20: natural-led; ceiling fan | H20: open concept | I20: smooth | J20: freestanding | K20: airy | L20: Mid-range | M20: No | N20: ceiling fan and open living-dining, suits SG climate | O20: Jose Gonzalez (@gdesignc) | P20: https://unsplash.com/photos/5OWwWbutc_g | Q20: Unsplash Licence
... A30: FL-0029 | B30: master bedroom | C30: HDB; condo | D30: modern minimalist | E30: warm neutral; beige, oak | F30: light wood; fabric-heavy | G30: cove; warm ambient | H30: closed | I30: soft layered | J30: built-in heavy | K30: calm | L30: Mid-range | M30: Likely | N30: arched timber headboard niche | O30: Spl Interiors (@spl_interiors) | P30: https://unsplash.com/photos/0tVimluL_ls | Q30: Unsplash Licence
A31: FL-0030 | B31: master bedroom | C31: condo; landed | D31: modern minimalist | E31: cool neutral; charcoal, grey, walnut | F31: concrete; dark wood; fabric-heavy | G31: natural-led | H31: closed | I31: soft layered | J31: built-in heavy | K31: calm | L31: Premium | M31: No | O31: Le Quan (@mrkheu) | P31: https://unsplash.com/photos/ErDrzSvSNv4 | Q31: Unsplash Licence
A32: FL-0031 | B32: master bedroom | C32: HDB; condo | D32: modern minimalist | E32: warm neutral; grey, walnut | F32: dark wood; fabric-heavy | G32: cove; warm ambient | H32: closed | I32: soft layered | J32: built-in heavy | K32: calm | L32: Mid-range | M32: Likely | N32: built-in shelving beside the bed | O32: POOJAN THANEKAR (@poojanclicks) | P32: https://unsplash.com/photos/u-RIsXlI8Q8 | Q32: Unsplash Licence
A33: FL-0032 | B33: master bedroom | C33: landed | D33: tropical | E33: earthy; dark teak, cream, teal | F33: dark wood; fabric-heavy | G33: warm ambient; cove | H33: closed | I33: soft layered | J33: built-in heavy | K33: cosy | L33: Premium | M33: No | N33: resort style with garden view | O33: visualsofdana (@visualsofdana) | P33: https://unsplash.com/photos/T5pL6ciEn-I | Q33: Unsplash Licence
A34: FL-0033 | B34: master bedroom | C34: HDB; condo | D34: tropical | E34: warm neutral; white, rattan, blush | F34: rattan; fabric-heavy | G34: natural-led | H34: closed | I34: woven | J34: freestanding | K34: airy | L34: Essential | M34: No | N34: rattan headboard and jute rug, low-cost look | O34: Alex Tyson (@alextyson195) | P34: https://unsplash.com/photos/W-wNHts_g3I | Q34: Unsplash Licence
A35: FL-0034 | B35: kitchen | C35: condo; landed | D35: modern minimalist | E35: warm neutral; white, oak | F35: light wood; marble | G35: natural-led; feature pendant | H35: open concept | I35: smooth | J35: built-in heavy | K35: airy | L35: Premium | M35: No | N35: reclassified from Japandi, reads as modern minimalist; marble floor and full-height cabinetry | O35: Brian Zajac (@brianzajac) | P35: https://unsplash.com/photos/lE7pmNZZ3Fw | Q35: Unsplash Licence
A36: FL-0035 | B36: kitchen | C36: HDB; condo | D36: Scandinavian | E36: warm neutral; greige, walnut | F36: dark wood; rattan; metal | G36: warm ambient; cove; feature pendant | H36: open concept | I36: woven | J36: built-in heavy | K36: cosy | L36: Mid-range | M36: Likely | N36: compact dining-kitchen, close to a condo layout | O36: POOJAN THANEKAR (@poojanclicks) | P36: https://unsplash.com/photos/cmuuvD2osWs | Q36: Unsplash Licence
A37: FL-0036 | B37: kitchen | C37: HDB; condo | D37: Scandinavian | E37: monochrome with light wood; black, white, oak | F37: light wood; metal | G37: natural-led; feature pendant | H37: open concept | I37: smooth | J37: built-in heavy | K37: airy | L37: Mid-range | M37: No | O37: krishna kumar c (@krishna_147) | P37: https://unsplash.com/photos/j6MCxix3o2c | Q37: Unsplash Licence
A38: FL-0037 | B38: kitchen | C38: condo; landed | D38: contemporary | E38: monochrome with wood; black, oak, white | F38: light wood; marble; metal | G38: cove; feature pendant | H38: open concept | I38: smooth | J38: built-in heavy | K38: dramatic | L38: Premium | M38: No | N38: fluted island, open to dining | O38: Anand Kumar (@elathi) | P38: https://unsplash.com/photos/AgHJm3uKr4U | Q38: Unsplash Licence
A39: FL-0038 | B39: kitchen | C39: condo; landed | D39: contemporary | E39: earthy; walnut, black, brass | F39: dark wood; metal | G39: warm ambient; feature pendant | H39: open concept | I39: smooth | J39: built-in heavy | K39: dramatic | L39: Premium | M39: Likely | O39: Alina Tramontana (@render_innovate3d) | P39: https://unsplash.com/photos/kAa2xEs_jZo | Q39: Unsplash Licence
A40: FL-0039 | B40: kitchen | C40: condo; landed | D40: industrial | E40: cool neutral; charcoal, concrete, oak | F40: concrete; metal; light wood | G40: cove; natural-led | H40: open concept | I40: raw | J40: built-in heavy | K40: dramatic | L40: Premium | M40: No | O40: Jean-Philippe Delberghe (@jipy32) | P40: https://unsplash.com/photos/4jxGry4pXtc | Q40: Unsplash Licence
A41: FL-0040 | B41: kitchen | C41: HDB; condo | D41: industrial | E41: bold; black, honey wood, white | F41: light wood; metal | G41: feature pendant; natural-led | H41: open concept | I41: raw | J41: built-in heavy | K41: playful | L41: Mid-range | M41: No | N41: open shelving; may be a cafe counter rather than a home kitchen | O41: Petr (@mpetrucho) | P41: https://unsplash.com/photos/Obh4ZS_bbno | Q41: Unsplash Licence
A42: FL-0041 | B42: kitchen | C42: condo; landed | D42: mid-century | E42: warm neutral with bold accent; walnut, white, red | F42: dark wood; marble | G42: natural-led | H42: open concept | I42: smooth | J42: built-in heavy | K42: cosy | L42: Premium | M42: No | N42: walnut upper cabinets, statement red range | O42: André François McKenzie (@silverhousehd) | P42: https://unsplash.com/photos/sZ5CteK2r6E | Q42: Unsplash Licence
A43: FL-0042 | B43: kitchen | C43: condo; landed | D43: mid-century | E43: warm neutral; white, walnut | F43: dark wood; metal | G43: feature pendant; natural-led | H43: open concept | I43: smooth | J43: built-in heavy | K43: airy | L43: Premium | M43: No | N43: globe pendants over a walnut island | O43: roam in color (@roamincolor) | P43: https://unsplash.com/photos/RryFk4n-vOs | Q43: Unsplash Licence
A44: FL-0043 | B44: kitchen | C44: condo; landed | D44: modern luxe | E44: warm neutral; greige, white marble | F44: marble; metal | G44: cove; feature pendant | H44: semi-open | I44: smooth | J44: built-in heavy | K44: calm | L44: Premium | M44: Likely | N44: book-matched marble backsplash with backlit display cabinets; likely a 3D render | O44: Medea Dzagnidze (@medeadza) | P44: https://unsplash.com/photos/1jy1WNfqHos | Q44: Unsplash Licence
A45: FL-0044 | B45: kitchen | C45: condo; landed | D45: modern luxe | E45: monochrome with gold; black, white marble, walnut | F45: marble; dark wood; metal | G45: feature pendant; cove | H45: open concept | I45: smooth | J45: built-in heavy | K45: dramatic | L45: Premium | M45: No | O45: Murat Demircan (@muratdemircan) | P45: https://unsplash.com/photos/c318EdSUtK4 | Q45: Unsplash Licence
A46: FL-0045 | B46: kitchen | C46: HDB; condo | D46: modern minimalist | E46: warm neutral; walnut, white, grey | F46: dark wood; metal | G46: feature pendant; cove | H46: open concept | I46: smooth | J46: built-in heavy | K46: calm | L46: Mid-range | M46: Likely | O46: SPurno Animation Studio (@spurno) | P46: https://unsplash.com/photos/80DAbtNfh4k | Q46: Unsplash Licence
A47: FL-0046 | B47: kitchen | C47: HDB; condo | D47: modern minimalist | E47: cool neutral; grey, white | F47: metal; light wood | G47: natural-led; cove | H47: semi-open | I47: smooth | J47: built-in heavy | K47: calm | L47: Mid-range | M47: No | N47: compact kitchen with dining nook, HDB-scale | O47: taufiq triadi (@mochamadtaufiq23) | P47: https://unsplash.com/photos/E7yGIdzNE3k | Q47: Unsplash Licence
A48: FL-0047 | B48: kitchen | C48: HDB; condo | D48: modern minimalist | E48: monochrome; white | F48: metal; marble | G48: natural-led | H48: closed | I48: smooth | J48: built-in heavy | K48: airy | L48: Essential | M48: No | N48: white galley layout, close to an HDB kitchen | O48: Simona Sergi (@i_am_simoesse) | P48: https://unsplash.com/photos/gijwI4X-7ig | Q48: Unsplash Licence
A49: FL-0048 | B49: kitchen | C49: landed | D49: tropical | E49: earthy; teak, black, green | F49: dark wood; metal | G49: natural-led; feature pendant | H49: open concept | I49: raw | J49: freestanding | K49: airy | L49: Premium | M49: No | N49: opens directly to garden, landed only | O49: Sanju Pandita (@spxclicks) | P49: https://unsplash.com/photos/_yynzKwlZOw | Q49: Unsplash Licence
...

Sheet Coverage
A1: Images per room and style (counts update from the Library tab)
A2: Room | B2: Scandinavian | C2: Japandi | D2: modern minimalist | E2: industrial | F2: mid-century | G2: contemporary | H2: tropical | I2: modern luxe | J2: Total
A3: living | B3: =COUNTIFS(Library!$B$2:$B$103,$A3,Library!$D$2:$D$103,B$2) -> 2 | C3: =COUNTIFS(Library!$B$2:$B$103,$A3,Library!$D$2:$D$103,C$2) -> 2 | D3: =COUNTIFS(Library!$B$2:$B$103,$A3,Library!$D$2:$D$103,D$2) -> 3 | E3: =COUNTIFS(Library!$B$2:$B$103,$A3,Library!$D$2:$D$103,E$2) -> 2 | F3: =COUNTIFS(Library!$B$2:$B$103,$A3,Library!$D$2:$D$103,F$2) -> 2 | G3: =COUNTIFS(Library!$B$2:$B$103,$A3,Library!$D$2:$D$103,G$2) -> 3 | H3: =COUNTIFS(Library!$B$2:$B$103,$A3,Library!$D$2:$D$103,H$2) -> 2 | I3: =COUNTIFS(Library!$B$2:$B$103,$A3,Library!$D$2:$D$103,I$2) -> 3 | J3: =SUM(B3:I3) -> 19
A4: master bedroom | B4: =COUNTIFS(Library!$B$2:$B$103,$A4,Library!$D$2:$D$103,B$2) -> 1 | C4: =COUNTIFS(Library!$B$2:$B$103,$A4,Library!$D$2:$D$103,C$2) -> 1 | D4: =COUNTIFS(Library!$B$2:$B$103,$A4,Library!$D$2:$D$103,D$2) -> 3 | E4: =COUNTIFS(Library!$B$2:$B$103,$A4,Library!$D$2:$D$103,E$2) -> 3 | F4: =COUNTIFS(Library!$B$2:$B$103,$A4,Library!$D$2:$D$103,F$2) -> 2 | G4: =COUNTIFS(Library!$B$2:$B$103,$A4,Library!$D$2:$D$103,G$2) -> 2 | H4: =COUNTIFS(Library!$B$2:$B$103,$A4,Library!$D$2:$D$103,H$2) -> 2 | I4: =COUNTIFS(Library!$B$2:$B$103,$A4,Library!$D$2:$D$103,I$2) -> 2 | J4: =SUM(B4:I4) -> 16
A5: kitchen | B5: =COUNTIFS(Library!$B$2:$B$103,$A5,Library!$D$2:$D$103,B$2) -> 2 | C5: =COUNTIFS(Library!$B$2:$B$103,$A5,Library!$D$2:$D$103,C$2) -> 2 | D5: =COUNTIFS(Library!$B$2:$B$103,$A5,Library!$D$2:$D$103,D$2) -> 4 | E5: =COUNTIFS(Library!$B$2:$B$103,$A5,Library!$D$2:$D$103,E$2) -> 2 | F5: =COUNTIFS(Library!$B$2:$B$103,$A5,Library!$D$2:$D$103,F$2) -> 2 | G5: =COUNTIFS(Library!$B$2:$B$103,$A5,Library!$D$2:$D$103,G$2) -> 2 | H5: =COUNTIFS(Library!$B$2:$B$103,$A5,Library!$D$2:$D$103,H$2) -> 2 | I5: =COUNTIFS(Library!$B$2:$B$103,$A5,Library!$D$2:$D$103,I$2) -> 2 | J5: =SUM(B5:I5) -> 18
A6: bathroom | B6: =COUNTIFS(Library!$B$2:$B$103,$A6,Library!$D$2:$D$103,B$2) -> 2 | C6: =COUNTIFS(Library!$B$2:$B$103,$A6,Library!$D$2:$D$103,C$2) -> 2 | D6: =COUNTIFS(Library!$B$2:$B$103,$A6,Library!$D$2:$D$103,D$2) -> 2 | E6: =COUNTIFS(Library!$B$2:$B$103,$A6,Library!$D$2:$D$103,E$2) -> 2 | F6: =COUNTIFS(Library!$B$2:$B$103,$A6,Library!$D$2:$D$103,F$2) -> 2 | G6: =COUNTIFS(Library!$B$2:$B$103,$A6,Library!$D$2:$D$103,G$2) -> 2 | H6: =COUNTIFS(Library!$B$2:$B$103,$A6,Library!$D$2:$D$103,H$2) -> 2 | I6: =COUNTIFS(Library!$B$2:$B$103,$A6,Library!$D$2:$D$103,I$2) -> 2 | J6: =SUM(B6:I6) -> 16
A7: study | B7: =COUNTIFS(Library!$B$2:$B$103,$A7,Library!$D$2:$D$103,B$2) -> 2 | C7: =COUNTIFS(Library!$B$2:$B$103,$A7,Library!$D$2:$D$103,C$2) -> 2 | D7: =COUNTIFS(Library!$B$2:$B$103,$A7,Library!$D$2:$D$103,D$2) -> 2 | E7: =COUNTIFS(Library!$B$2:$B$103,$A7,Library!$D$2:$D$103,E$2) -> 2 | F7: =COUNTIFS(Library!$B$2:$B$103,$A7,Library!$D$2:$D$103,F$2) -> 2 | G7: =COUNTIFS(Library!$B$2:$B$103,$A7,Library!$D$2:$D$103,G$2) -> 1 | H7: =COUNTIFS(Library!$B$2:$B$103,$A7,Library!$D$2:$D$103,H$2) -> 2 | I7: =COUNTIFS(Library!$B$2:$B$103,$A7,Library!$D$2:$D$103,I$2) -> 1 | J7: =SUM(B7:I7) -> 14
A8: dining | B8: =COUNTIFS(Library!$B$2:$B$103,$A8,Library!$D$2:$D$103,B$2) -> 1 | C8: =COUNTIFS(Library!$B$2:$B$103,$A8,Library!$D$2:$D$103,C$2) -> 1 | D8: =COUNTIFS(Library!$B$2:$B$103,$A8,Library!$D$2:$D$103,D$2) -> 1 | E8: =COUNTIFS(Library!$B$2:$B$103,$A8,Library!$D$2:$D$103,E$2) -> 1 | F8: =COUNTIFS(Library!$B$2:$B$103,$A8,Library!$D$2:$D$103,F$2) -> 2 | G8: =COUNTIFS(Library!$B$2:$B$103,$A8,Library!$D$2:$D$103,G$2) -> 1 | H8: =COUNTIFS(Library!$B$2:$B$103,$A8,Library!$D$2:$D$103,H$2) -> 1 | I8: =COUNTIFS(Library!$B$2:$B$103,$A8,Library!$D$2:$D$103,I$2) -> 1 | J8: =SUM(B8:I8) -> 9
A9: secondary bedroom | B9: =COUNTIFS(Library!$B$2:$B$103,$A9,Library!$D$2:$D$103,B$2) -> 2 | C9: =COUNTIFS(Library!$B$2:$B$103,$A9,Library!$D$2:$D$103,C$2) -> 0 | D9: =COUNTIFS(Library!$B$2:$B$103,$A9,Library!$D$2:$D$103,D$2) -> 1 | E9: =COUNTIFS(Library!$B$2:$B$103,$A9,Library!$D$2:$D$103,E$2) -> 0 | F9: =COUNTIFS(Library!$B$2:$B$103,$A9,Library!$D$2:$D$103,F$2) -> 1 | G9: =COUNTIFS(Library!$B$2:$B$103,$A9,Library!$D$2:$D$103,G$2) -> 1 | H9: =COUNTIFS(Library!$B$2:$B$103,$A9,Library!$D$2:$D$103,H$2) -> 0 | I9: =COUNTIFS(Library!$B$2:$B$103,$A9,Library!$D$2:$D$103,I$2) -> 0 | J9: =SUM(B9:I9) -> 5
A10: balcony | B10: =COUNTIFS(Library!$B$2:$B$103,$A10,Library!$D$2:$D$103,B$2) -> 0 | C10: =COUNTIFS(Library!$B$2:$B$103,$A10,Library!$D$2:$D$103,C$2) -> 0 | D10: =COUNTIFS(Library!$B$2:$B$103,$A10,Library!$D$2:$D$103,D$2) -> 1 | E10: =COUNTIFS(Library!$B$2:$B$103,$A10,Library!$D$2:$D$103,E$2) -> 1 | F10: =COUNTIFS(Library!$B$2:$B$103,$A10,Library!$D$2:$D$103,F$2) -> 0 | G10: =COUNTIFS(Library!$B$2:$B$103,$A10,Library!$D$2:$D$103,G$2) -> 1 | H10: =COUNTIFS(Library!$B$2:$B$103,$A10,Library!$D$2:$D$103,H$2) -> 0 | I10: =COUNTIFS(Library!$B$2:$B$103,$A10,Library!$D$2:$D$103,I$2) -> 0 | J10: =SUM(B10:I10) -> 3
A11: entryway | B11: =COUNTIFS(Library!$B$2:$B$103,$A11,Library!$D$2:$D$103,B$2) -> 1 | C11: =COUNTIFS(Library!$B$2:$B$103,$A11,Library!$D$2:$D$103,C$2) -> 0 | D11: =COUNTIFS(Library!$B$2:$B$103,$A11,Library!$D$2:$D$103,D$2) -> 0 | E11: =COUNTIFS(Library!$B$2:$B$103,$A11,Library!$D$2:$D$103,E$2) -> 0 | F11: =COUNTIFS(Library!$B$2:$B$103,$A11,Library!$D$2:$D$103,F$2) -> 0 | G11: =COUNTIFS(Library!$B$2:$B$103,$A11,Library!$D$2:$D$103,G$2) -> 1 | H11: =COUNTIFS(Library!$B$2:$B$103,$A11,Library!$D$2:$D$103,H$2) -> 0 | I11: =COUNTIFS(Library!$B$2:$B$103,$A11,Library!$D$2:$D$103,I$2) -> 0 | J11: =SUM(B11:I11) -> 2
A12: Total | B12: =SUM(B3:B11) -> 13 | C12: =SUM(C3:C11) -> 10 | D12: =SUM(D3:D11) -> 17 | E12: =SUM(E3:E11) -> 13 | F12: =SUM(F3:F11) -> 13 | G12: =SUM(G3:G11) -> 14 | H12: =SUM(H3:H11) -> 11 | I12: =SUM(I3:I11) -> 11 | J12: =SUM(J3:J11) -> 102
A14: By budget tier
A15: Essential | B15: =COUNTIF(Library!$L$2:$L$103,A15) -> 30
A16: Mid-range | B16: =COUNTIF(Library!$L$2:$L$103,A16) -> 42
A17: Premium | B17: =COUNTIF(Library!$L$2:$L$103,A17) -> 30
A18: Likely 3D renders | B18: =COUNTIF(Library!$M$2:$M$103,"Likely") -> 36

Sheet Budget tiers
A1: Tier | B1: Whole-home budget (SGD) | C1: What the reference photos show | D1: Typical fit
A2: Essential | B2: Under 40,000 | C2: Laminate carpentry, vinyl flooring, loose furniture, few built-ins | D2: BTO and smaller HDB flats, new condos with light scope
A3: Mid-range | B3: 40,000 to 80,000 | C3: Custom carpentry, feature walls, cove lighting, upgraded bathrooms | D3: Most 4 to 5-room HDB and new condo renovations
A4: Premium | B4: Above 80,000 | C4: Stone, extensive joinery, bespoke lighting, structural changes | D4: Resale condos with full works, landed homes (usually from 120,000)
A6: How to use | B6: The tier on each image describes its finish level, not a price for the client's home. The homeowner's Stage 2 bracket maps onto the tier. Tiers on images are visual estimates and should be confirmed.
A7: Evidence strength | B7: Boundaries come from 2026 contractor and interior design firm guides. About eight firms give consistent ranges, but none is independent survey data, so the brackets are indicative planning anchors.
A9: Sources
B10: Design Authority, Singapore Renovation Cost 2026 (3-room BTO about 25,000 to 45,000; 4-room BTO 40,300 to 62,300; resale 20 to 40% higher): https://design-authority.com/singapore-renovation-cost-2026-guide/
B11: RCS, HDB Renovation Packages 2026 (a 25,000 budget works for BTO only): https://renovationcontractorsingapore.com/blogs/news/hdb-renovation-packages-price-list-singapore-2026
B12: ShiokNest, Condo Renovation Cost 2026 (new condo 25,000 to 70,000; resale condo 48,000 to 92,000): https://shioknest.com/guides/guide-renovation-budgeting-new-condo-owners
B13: T Se7en, Home Renovation Cost Singapore 2026 (landed from about 120,000): https://www.tse7en.com/home-renovation-cost-in-singapore/

Sheet Tag vocabulary
A1: Field | B1: Allowed values | C1: Values per image
A2: Room type | B2: living, master bedroom, kitchen, bathroom, study, dining, secondary bedroom, balcony, entryway | C2: one
A3: Housing fit (est.) | B3: HDB, condo, landed | C3: multi
A4: Style | B4: Scandinavian, Japandi, modern minimalist, industrial, mid-century, contemporary, tropical, modern luxe | C4: one
A5: Palette | B5: warm neutral, cool neutral, monochrome, earthy, pastel, bold, followed by dominant colours | C5: multi
A6: Materials | B6: light wood, dark wood, rattan, marble, terrazzo, concrete, metal, fabric-heavy | C6: multi
A7: Lighting | B7: natural-led, warm ambient, cool task, feature pendant, cove (plus fixtures noted such as ceiling fan, floor lamp) | C7: multi
A8: Layout | B8: open concept, semi-open, closed | C8: one
A9: Textiles and texture | B9: smooth, soft layered, woven, raw | C9: one
A10: Furniture style | B10: low-profile, built-in heavy, freestanding, statement piece | C10: one
A11: Mood | B11: calm, cosy, airy, dramatic, playful | C11: one
A12: Budget tier (est.) | B12: Essential, Mid-range, Premium (see Budget tiers tab) | C12: one
A13: Photo or render | B13: No, Likely (flagged from visual cues and the uploader being a 3D or design studio) | C13: one
A15: Client uploads are extracted into the same vocabulary so their tags can rank library images directly.

Sheet Gaps and caveats
A1: Item | B1: Detail
A2: Thin cells | B2: Balcony and entryway have two or three images each and are not split by style. Study has one image each for contemporary and modern luxe. Secondary bedroom covers four styles only.
A3: Reclassified row | B3: The earlier Japandi kitchen (Unsplash lE7pmNZZ3Fw) is now tagged modern minimalist, since two stronger Japandi kitchens were added.
A4: Singapore-specific spaces | B4: Few images show HDB features such as bomb shelters or service yards. Rows noting HDB-like footprints (louvred shoe cabinets, compact galley kitchens, washers in bathrooms, wall-mounted aircon) are the closest matches.
A5: Renders | B5: Several images are likely 3D renders rather than photographs. They are marked in the Photo or render column. Keep them if the demo only needs style references, or swap them if you want real homes only.
A6: Tag method | B6: Tags were assigned by eye from thumbnails. Budget tier and housing fit are the least reliable fields and should be spot-checked.
A7: Licence | B7: All images are free Unsplash images (Unsplash+ excluded). The Unsplash Licence allows commercial use but bars compiling photos to build a similar or competing service. A tagged library is probably fine for a competition demo, but a production version would need its own licensed library.
A8: Attribution | B8: Unsplash does not require credit, but crediting the photographer in the app is good practice and the Photographer column supports that.
